Workbook

Sheet Validation
A1: CaseID | B1: Individual | C1: Classes | D1: #Classes | E1: Class #1 | F1: Hallucinated class #1 | H1: Class #2 | I1: Hallucinated class #2 | J1: Class #3 | K1: Hallucinated class #3 | L1: ObjectProperties | M1: DataProperties | N1: Annotations | O1: MissingType | P1: WrongClasses | Q1: WrongProperties | R1: Define source | S1: Related concept | T1: Group of concepts | U1: Unsolicited | V1: Hallucination_any | W1: Hallucination_Structural | X1: Hallucination_Semantic | Y1: Hallucination_Contextual | Z1: Hallucination_Evidence | AA1: Explanation_Generated
A2: UC1-F1-P1-S1-M1 | B2: BTD_BiotinTreatment_AnnualCost | C2: CostParameter | D2: =IF(ISBLANK(C2),0,LEN(C2)-LEN(SUBSTITUTE(C2,";",""))+1) -> 1 | E2: =IF(D2<2,C2,LEFT(C2,FIND(";",C2)-1)) -> CostParameter | F2: =IF(D2<1,FALSE,ISERROR(MATCH(E2,'Ontology and concepts per UC'!$A$2:$A$62,0))) -> TRUE | G2: =IF(D2<2,"",MID(C2,LEN(E2)+3,LEN(C2)-FIND(";",C2)-1)) | H2: =IF(D2<3,G2,LEFT(G2,FIND(";",G2)-1)) | I2: =IF(D2<2,FALSE,ISERROR(MATCH(H2,'Ontology and concepts per UC'!$A$2:$A$62,0))) -> FALSE | J2: =IF(D2<3,"",RIGHT(G2,LEN(G2)-FIND(";",G2)-1)) | K2: =IF(D2<3,FALSE,ISERROR(MATCH(J2,'Ontology and concepts per UC'!$A$2:$A$62,0))) -> FALSE | M2: hasDescription:"Coste anual del tratamiento con biotina (5-10 mg/día)"; hasUnit:"EUR"; hasExpectedValue:"730"; | O2: FALSE | P2: 1 | Q2: 0 | R2: =NOT(ISERROR(SEARCH("hasSource",M2))) -> FALSE | S2: Coste tratamiento | T2: =IF(S2="","",VLOOKUP(S2,'Ontology and concepts per UC'!$F$2:$J$46,5,FALSE)) -> Coste | U2: {=(INDEX('Ontology and concepts per UC'!$G$2:$I$46,MATCH($S2,'Ontology and concepts per UC'!$F$2:$F$46,0),MATCH(LEFT($A2,3),'Ontology and concepts per UC'!$G$1:$I$1,0))=0)} -> FALSE | V2: =COUNTIF(W2:Z2,TRUE)>0 -> TRUE | W2: TRUE | X2: FALSE | Y2: FALSE | Z2: FALSE | AA2: Class 'CostParameter' undefined
A3: UC1-F1-P1-S1-M1 | B3: BTD_DiagnosticTest_Cost | C3: CostParameter | D3: =IF(ISBLANK(C3),0,LEN(C3)-LEN(SUBSTITUTE(C3,";",""))+1) -> 1 | E3: =IF(D3<2,C3,LEFT(C3,FIND(";",C3)-1)) -> CostParameter | F3: =IF(D3<1,FALSE,ISERROR(MATCH(E3,'Ontology and concepts per UC'!$A$2:$A$62,0))) -> TRUE | G3: =IF(D3<2,"",MID(C3,LEN(E3)+3,LEN(C3)-FIND(";",C3)-1)) | H3: =IF(D3<3,G3,LEFT(G3,FIND(";",G3)-1)) | I3: =IF(D3<2,FALSE,ISERROR(MATCH(H3,'Ontology and concepts per UC'!$A$2:$A$62,0))) -> FALSE | J3: =IF(D3<3,"",RIGHT(G3,LEN(G3)-FIND(";",G3)-1)) | K3: =IF(D3<3,FALSE,ISERROR(MATCH(J3,'Ontology and concepts per UC'!$A$2:$A$62,0))) -> FALSE | M3: hasDescription:"Coste de la prueba diagnóstica confirmatoria"; hasExpectedValue:"150"; | O3: FALSE | P3: 1 | Q3: 0 | R3: =NOT(ISERROR(SEARCH("hasSource",M3))) -> FALSE | S3: Coste de diagnóstico | T3: =IF(S3="","",VLOOKUP(S3,'Ontology and concepts per UC'!$F$2:$J$46,5,FALSE)) -> Coste | U3: {=(INDEX('Ontology and concepts per UC'!$G$2:$I$46,MATCH($S3,'Ontology and concepts per UC'!$F$2:$F$46,0),MATCH(LEFT($A3,3),'Ontology and concepts per UC'!$G$1:$I$1,0))=0)} -> FALSE | V3: =COUNTIF(W3:Z3,TRUE)>0 -> TRUE | W3: TRUE | X3: FALSE | Y3: FALSE | Z3: FALSE | AA3: Class 'CostParameter' undefined
A4: UC1-F1-P1-S1-M1 | B4: BTD_Screening_Cost | C4: CostParameter | D4: =IF(ISBLANK(C4),0,LEN(C4)-LEN(SUBSTITUTE(C4,";",""))+1) -> 1 | E4: =IF(D4<2,C4,LEFT(C4,FIND(";",C4)-1)) -> CostParameter | F4: =IF(D4<1,FALSE,ISERROR(MATCH(E4,'Ontology and concepts per UC'!$A$2:$A$62,0))) -> TRUE | G4: =IF(D4<2,"",MID(C4,LEN(E4)+3,LEN(C4)-FIND(";",C4)-1)) | H4: =IF(D4<3,G4,LEFT(G4,FIND(";",G4)-1)) | I4: =IF(D4<2,FALSE,ISERROR(MATCH(H4,'Ontology and concepts per UC'!$A$2:$A$62,0))) -> FALSE | J4: =IF(D4<3,"",RIGHT(G4,LEN(G4)-FIND(";",G4)-1)) | K4: =IF(D4<3,FALSE,ISERROR(MATCH(J4,'Ontology and concepts per UC'!$A$2:$A$62,0))) -> FALSE | M4: hasExpectedValue:"3.50"; hasDescription:"Coste del cribado neonatal por recién nacido"; hasUnit:"EUR"; | O4: FALSE | P4: 1 | Q4: 0 | R4: =NOT(ISERROR(SEARCH("hasSource",M4))) -> FALSE | S4: Coste cribado | T4: =IF(S4="","",VLOOKUP(S4,'Ontology and concepts per UC'!$F$2:$J$46,5,FALSE)) -> Coste | U4: {=(INDEX('Ontology and concepts per UC'!$G$2:$I$46,MATCH($S4,'Ontology and concepts per UC'!$F$2:$F$46,0),MATCH(LEFT($A4,3),'Ontology and concepts per UC'!$G$1:$I$1,0))=0)} -> FALSE | V4: =COUNTIF(W4:Z4,TRUE)>0 -> TRUE | W4: TRUE | X4: FALSE | Y4: FALSE | Z4: FALSE | AA4: Class 'CostParameter' undefined
A5: UC1-F1-P1-S1-M1 | B5: BTD_Disease_Partial | C5: Disease | D5: =IF(ISBLANK(C5),0,LEN(C5)-LEN(SUBSTITUTE(C5,";",""))+1) -> 1 | E5: =IF(D5<2,C5,LEFT(C5,FIND(";",C5)-1)) -> Disease | F5: =IF(D5<1,FALSE,ISERROR(MATCH(E5,'Ontology and concepts per UC'!$A$2:$A$62,0))) -> FALSE | G5: =IF(D5<2,"",MID(C5,LEN(E5)+3,LEN(C5)-FIND(";",C5)-1)) | H5: =IF(D5<3,G5,LEFT(G5,FIND(";",G5)-1)) | I5: =IF(D5<2,FALSE,ISERROR(MATCH(H5,'Ontology and concepts per UC'!$A$2:$A$62,0))) -> FALSE | J5: =IF(D5<3,"",RIGHT(G5,LEN(G5)-FIND(";",G5)-1)) | K5: =IF(D5<3,FALSE,ISERROR(MATCH(J5,'Ontology and concepts per UC'!$A$2:$A$62,0))) -> FALSE | L5: isSubtypeOf:BTD_Disease; | M5: hasDescription:"Deficiencia parcial de biotinidasa (actividad enzimática 10-30% del valor normal)"; | O5: FALSE | P5: 0 | Q5: 1 | R5: =NOT(ISERROR(SEARCH("hasSource",M5))) -> FALSE | S5: Parcial | T5: =IF(S5="","",VLOOKUP(S5,'Ontology and concepts per UC'!$F$2:$J$46,5,FALSE)) -> Parcial | U5: {=(INDEX('Ontology and concepts per UC'!$G$2:$I$46,MATCH($S5,'Ontology and concepts per UC'!$F$2:$F$46,0),MATCH(LEFT($A5,3),'Ontology and concepts per UC'!$G$1:$I$1,0))=0)} -> FALSE | V5: =COUNTIF(W5:Z5,TRUE)>0 -> TRUE | W5: TRUE | X5: FALSE | Y5: FALSE | Z5: FALSE | AA5: ObjectProp 'isSubtypeOf' undefined
A6: UC1-F1-P1-S1-M1 | B6: BTD_Disease_Profound | C6: Disease | D6: =IF(ISBLANK(C6),0,LEN(C6)-LEN(SUBSTITUTE(C6,";",""))+1) -> 1 | E6: =IF(D6<2,C6,LEFT(C6,FIND(";",C6)-1)) -> Disease | F6: =IF(D6<1,FALSE,ISERROR(MATCH(E6,'Ontology and concepts per UC'!$A$2:$A$62,0))) -> FALSE | G6: =IF(D6<2,"",MID(C6,LEN(E6)+3,LEN(C6)-FIND(";",C6)-1)) | H6: =IF(D6<3,G6,LEFT(G6,FIND(";",G6)-1)) | I6: =IF(D6<2,FALSE,ISERROR(MATCH(H6,'Ontology and concepts per UC'!$A$2:$A$62,0))) -> FALSE | J6: =IF(D6<3,"",RIGHT(G6,LEN(G6)-FIND(";",G6)-1)) | K6: =IF(D6<3,FALSE,ISERROR(MATCH(J6,'Ontology and concepts per UC'!$A$2:$A$62,0))) -> FALSE | L6: hasFeature:BTD_Manif_OpticAtrophy; hasFeature:BTD_Manif_DevelopmentalDelay; hasFeature:BTD_Manif_Seizures; hasFeature:BTD_Manif_HearingLoss; hasFeature:BTD_Manif_SkinProblems; hasFeature:BTD_Manif_Hypotonia; isSubtypeOf:BTD_Disease; | M6: hasDescription:"Deficiencia profunda de biotinidasa (actividad enzimática menor del 10% del valor normal)"; | O6: FALSE | P6: 0 | Q6: 7 | R6: =NOT(ISERROR(SEARCH("hasSource",M6))) -> FALSE | S6: Enfermedad | T6: =IF(S6="","",VLOOKUP(S6,'Ontology and concepts per UC'!$F$2:$J$46,5,FALSE)) -> Modelo Conceptual | U6: {=(INDEX('Ontology and concepts per UC'!$G$2:$I$46,MATCH($S6,'Ontology and concepts per UC'!$F$2:$F$46,0),MATCH(LEFT($A6,3),'Ontology and concepts per UC'!$G$1:$I$1,0))=0)} -> FALSE | V6: =COUNTIF(W6:Z6,TRUE)>0 -> TRUE | W6: TRUE | X6: FALSE | Y6: FALSE | Z6: FALSE | AA6: ObjectProp 'hasFeature' undefined; ObjectProp 'isSubtypeOf' undefined
A7: UC1-F1-P1-S1-M1 | B7: BTD_FollowUp_AnnualMonitoring | C7: FollowUpStrategy | D7: =IF(ISBLANK(C7),0,LEN(C7)-LEN(SUBSTITUTE(C7,";",""))+1) -> 1 | E7: =IF(D7<2,C7,LEFT(C7,FIND(";",C7)-1)) -> FollowUpStrategy | F7: =IF(D7<1,FALSE,ISERROR(MATCH(E7,'Ontology and concepts per UC'!$A$2:$A$62,0))) -> FALSE | G7: =IF(D7<2,"",MID(C7,LEN(E7)+3,LEN(C7)-FIND(";",C7)-1)) | H7: =IF(D7<3,G7,LEFT(G7,FIND(";",G7)-1)) | I7: =IF(D7<2,FALSE,ISERROR(MATCH(H7,'Ontology and concepts per UC'!$A$2:$A$62,0))) -> FALSE | J7: =IF(D7<3,"",RIGHT(G7,LEN(G7)-FIND(";",G7)-1)) | K7: =IF(D7<3,FALSE,ISERROR(MATCH(J7,'Ontology and concepts per UC'!$A$2:$A$62,0))) -> FALSE | O7: FALSE | P7: 0 | Q7: 0 | R7: =NOT(ISERROR(SEARCH("hasSource",M7))) -> FALSE | S7: Seguimiento | T7: =IF(S7="","",VLOOKUP(S7,'Ontology and concepts per UC'!$F$2:$J$46,5,FALSE)) -> Tratamiento/seguimiento | U7: {=(INDEX('Ontology and concepts per UC'!$G$2:$I$46,MATCH($S7,'Ontology and concepts per UC'!$F$2:$F$46,0),MATCH(LEFT($A7,3),'Ontology and concepts per UC'!$G$1:$I$1,0))=0)} -> FALSE | V7: =COUNTIF(W7:Z7,TRUE)>0 -> FALSE | W7: FALSE | X7: FALSE | Y7: FALSE | Z7: FALSE
A8: UC1-F1-P1-S1-M1 | B8: BTD_Intervention_BiotinTreatment | C8: Intervention | D8: =IF(ISBLANK(C8),0,LEN(C8)-LEN(SUBSTITUTE(C8,";",""))+1) -> 1 | E8: =IF(D8<2,C8,LEFT(C8,FIND(";",C8)-1)) -> Intervention | F8: =IF(D8<1,FALSE,ISERROR(MATCH(E8,'Ontology and concepts per UC'!$A$2:$A$62,0))) -> FALSE | G8: =IF(D8<2,"",MID(C8,LEN(E8)+3,LEN(C8)-FIND(";",C8)-1)) | H8: =IF(D8<3,G8,LEFT(G8,FIND(";",G8)-1)) | I8: =IF(D8<2,FALSE,ISERROR(MATCH(H8,'Ontology and concepts per UC'!$A$2:$A$62,0))) -> FALSE | J8: =IF(D8<3,"",RIGHT(G8,LEN(G8)-FIND(";",G8)-1)) | K8: =IF(D8<3,FALSE,ISERROR(MATCH(J8,'Ontology and concepts per UC'!$A$2:$A$62,0))) -> FALSE | L8: hasTreatmentCost:BTD_BiotinTreatment_AnnualCost; | M8: hasDescription:"Tratamiento con biotina oral (5-30 mg/día)"; | O8: FALSE | P8: 0 | Q8: 0 | R8: =NOT(ISERROR(SEARCH("hasSource",M8))) -> FALSE | S8: Tratamiento base | T8: =IF(S8="","",VLOOKUP(S8,'Ontology and concepts per UC'!$F$2:$J$46,5,FALSE)) -> Tratamiento/seguimiento | U8: {=(INDEX('Ontology and concepts per UC'!$G$2:$I$46,MATCH($S8,'Ontology and concepts per UC'!$F$2:$F$46,0),MATCH(LEFT($A8,3),'Ontology and concepts per UC'!$G$1:$I$1,0))=0)} -> FALSE | V8: =COUNTIF(W8:Z8,TRUE)>0 -> TRUE | W8: FALSE | X8: FALSE | Y8: FALSE | Z8: TRUE | AA8: Should not be an Intervention
A9: UC1-F1-P1-S1-M1 | B9: BTD_Intervention_ClinicalDiagnosis | C9: Intervention | D9: =IF(ISBLANK(C9),0,LEN(C9)-LEN(SUBSTITUTE(C9,";",""))+1) -> 1 | E9: =IF(D9<2,C9,LEFT(C9,FIND(";",C9)-1)) -> Intervention | F9: =IF(D9<1,FALSE,ISERROR(MATCH(E9,'Ontology and concepts per UC'!$A$2:$A$62,0))) -> FALSE | G9: =IF(D9<2,"",MID(C9,LEN(E9)+3,LEN(C9)-FIND(";",C9)-1)) | H9: =IF(D9<3,G9,LEFT(G9,FIND(";",G9)-1)) | I9: =IF(D9<2,FALSE,ISERROR(MATCH(H9,'Ontology and concepts per UC'!$A$2:$A$62,0))) -> FALSE | J9: =IF(D9<3,"",RIGHT(G9,LEN(G9)-FIND(";",G9)-1)) | K9: =IF(D9<3,FALSE,ISERROR(MATCH(J9,'Ontology and concepts per UC'!$A$2:$A$62,0))) -> FALSE | M9: hasDescription:"Detección clínica de la deficiencia de biotinidasa tras aparición de síntomas"; | O9: FALSE | P9: 0 | Q9: 0 | R9: =NOT(ISERROR(SEARCH("hasSource",M9))) -> FALSE | S9: Intervención: No cribado | T9: =IF(S9="","",VLOOKUP(S9,'Ontology and concepts per UC'!$F$2:$J$46,5,FALSE)) -> Modelo Conceptual | U9: {=(INDEX('Ontology and concepts per UC'!$G$2:$I$46,MATCH($S9,'Ontology and concepts per UC'!$F$2:$F$46,0),MATCH(LEFT($A9,3),'Ontology and concepts per UC'!$G$1:$I$1,0))=0)} -> FALSE | V9: =COUNTIF(W9:Z9,TRUE)>0 -> FALSE | W9: FALSE | X9: FALSE | Y9: FALSE | Z9: FALSE
A10: UC1-F1-P1-S1-M1 | B10: BTD_Intervention_Screening | C10: Intervention | D10: =IF(ISBLANK(C10),0,LEN(C10)-LEN(SUBSTITUTE(C10,";",""))+1) -> 1 | E10: =IF(D10<2,C10,LEFT(C10,FIND(";",C10)-1)) -> Intervention | F10: =IF(D10<1,FALSE,ISERROR(MATCH(E10,'Ontology and concepts per UC'!$A$2:$A$62,0))) -> FALSE | G10: =IF(D10<2,"",MID(C10,LEN(E10)+3,LEN(C10)-FIND(";",C10)-1)) | H10: =IF(D10<3,G10,LEFT(G10,FIND(";",G10)-1)) | I10: =IF(D10<2,FALSE,ISERROR(MATCH(H10,'Ontology and concepts per UC'!$A$2:$A$62,0))) -> FALSE | J10: =IF(D10<3,"",RIGHT(G10,LEN(G10)-FIND(";",G10)-1)) | K10: =IF(D10<3,FALSE,ISERROR(MATCH(J10,'Ontology and concepts per UC'!$A$2:$A$62,0))) -> FALSE | L10: modifies:BTD_Manif_HearingLoss_Prob_WithoutTreatment; | M10: hasDescription:"Cribado neonatal de la deficiencia de biotinidasa mediante ensayo enzimático o fluorimétrico semicuantitativo"; | O10: FALSE | P10: 0 | Q10: 0 | R10: =NOT(ISERROR(SEARCH("hasSource",M10))) -> FALSE | S10: Intervención: Cribado | T10: =IF(S10="","",VLOOKUP(S10,'Ontology and concepts per UC'!$F$2:$J$46,5,FALSE)) -> Modelo Conceptual | U10: {=(INDEX('Ontology and concepts per UC'!$G$2:$I$46,MATCH($S10,'Ontology and concepts per UC'!$F$2:$F$46,0),MATCH(LEFT($A10,3),'Ontology and concepts per UC'!$G$1:$I$1,0))=0)} -> FALSE | V10: =COUNTIF(W10:Z10,TRUE)>0 -> FALSE | W10: FALSE | X10: FALSE | Y10: FALSE | Z10: FALSE
A11: UC1-F1-P1-S1-M1 | B11: BTD_Manif_DevelopmentalDelay | C11: Manifestation | D11: =IF(ISBLANK(C11),0,LEN(C11)-LEN(SUBSTITUTE(C11,";",""))+1) -> 1 | E11: =IF(D11<2,C11,LEFT(C11,FIND(";",C11)-1)) -> Manifestation | F11: =IF(D11<1,FALSE,ISERROR(MATCH(E11,'Ontology and concepts per UC'!$A$2:$A$62,0))) -> FALSE | G11: =IF(D11<2,"",MID(C11,LEN(E11)+3,LEN(C11)-FIND(";",C11)-1)) | H11: =IF(D11<3,G11,LEFT(G11,FIND(";",G11)-1)) | I11: =IF(D11<2,FALSE,ISERROR(MATCH(H11,'Ontology and concepts per UC'!$A$2:$A$62,0))) -> FALSE | J11: =IF(D11<3,"",RIGHT(G11,LEN(G11)-FIND(";",G11)-1)) | K11: =IF(D11<3,FALSE,ISERROR(MATCH(J11,'Ontology and concepts per UC'!$A$2:$A$62,0))) -> FALSE | M11: hasDescription:"Retraso del desarrollo psicomotor"; | O11: FALSE | P11: 0 | Q11: 0 | R11: =NOT(ISERROR(SEARCH("hasSource",M11))) -> FALSE | S11: Manifestación: Retraso mental | T11: =IF(S11="","",VLOOKUP(S11,'Ontology and concepts per UC'!$F$2:$J$46,5,FALSE)) -> Modelo Conceptual | U11: {=(INDEX('Ontology and concepts per UC'!$G$2:$I$46,MATCH($S11,'Ontology and concepts per UC'!$F$2:$F$46,0),MATCH(LEFT($A11,3),'Ontology and concepts per UC'!$G$1:$I$1,0))=0)} -> FALSE | V11: =COUNTIF(W11:Z11,TRUE)>0 -> FALSE | W11: FALSE | X11: FALSE | Y11: FALSE | Z11: FALSE
A12: UC1-F1-P1-S1-M1 | B12: BTD_Manif_HearingLoss | C12: Manifestation | D12: =IF(ISBLANK(C12),0,LEN(C12)-LEN(SUBSTITUTE(C12,";",""))+1) -> 1 | E12: =IF(D12<2,C12,LEFT(C12,FIND(";",C12)-1)) -> Manifestation | F12: =IF(D12<1,FALSE,ISERROR(MATCH(E12,'Ontology and concepts per UC'!$A$2:$A$62,0))) -> FALSE | G12: =IF(D12<2,"",MID(C12,LEN(E12)+3,LEN(C12)-FIND(";",C12)-1)) | H12: =IF(D12<3,G12,LEFT(G12,FIND(";",G12)-1)) | I12: =IF(D12<2,FALSE,ISERROR(MATCH(H12,'Ontology and concepts per UC'!$A$2:$A$62,0))) -> FALSE | J12: =IF(D12<3,"",RIGHT(G12,LEN(G12)-FIND(";",G12)-1)) | K12: =IF(D12<3,FALSE,ISERROR(MATCH(J12,'Ontology and concepts per UC'!$A$2:$A$62,0))) -> FALSE | M12: hasDescription:"Pérdida auditiva neurosensorial"; | O12: FALSE | P12: 0 | Q12: 0 | R12: =NOT(ISERROR(SEARCH("hasSource",M12))) -> FALSE | S12: Manifestación: Problemas de audición | T12: =IF(S12="","",VLOOKUP(S12,'Ontology and concepts per UC'!$F$2:$J$46,5,FALSE)) -> Modelo Conceptual | U12: {=(INDEX('Ontology and concepts per UC'!$G$2:$I$46,MATCH($S12,'Ontology and concepts per UC'!$F$2:$F$46,0),MATCH(LEFT($A12,3),'Ontology and concepts per UC'!$G$1:$I$1,0))=0)} -> FALSE | V12: =COUNTIF(W12:Z12,TRUE)>0 -> FALSE | W12: FALSE | X12: FALSE | Y12: FALSE | Z12: FALSE
A13: UC1-F1-P1-S1-M1 | B13: BTD_Manif_Hypotonia | C13: Manifestation | D13: =IF(ISBLANK(C13),0,LEN(C13)-LEN(SUBSTITUTE(C13,";",""))+1) -> 1 | E13: =IF(D13<2,C13,LEFT(C13,FIND(";",C13)-1)) -> Manifestation | F13: =IF(D13<1,FALSE,ISERROR(MATCH(E13,'Ontology and concepts per UC'!$A$2:$A$62,0))) -> FALSE | G13: =IF(D13<2,"",MID(C13,LEN(E13)+3,LEN(C13)-FIND(";",C13)-1)) | H13: =IF(D13<3,G13,LEFT(G13,FIND(";",G13)-1)) | I13: =IF(D13<2,FALSE,ISERROR(MATCH(H13,'Ontology and concepts per UC'!$A$2:$A$62,0))) -> FALSE | J13: =IF(D13<3,"",RIGHT(G13,LEN(G13)-FIND(";",G13)-1)) | K13: =IF(D13<3,FALSE,ISERROR(MATCH(J13,'Ontology and concepts per UC'!$A$2:$A$62,0))) -> FALSE | M13: hasDescription:"Hipotonía muscular"; | O13: FALSE | P13: 0 | Q13: 0 | R13: =NOT(ISERROR(SEARCH("hasSource",M13))) -> FALSE | S13: Manifestación: Hipotonía | T13: =IF(S13="","",VLOOKUP(S13,'Ontology and concepts per UC'!$F$2:$J$46,5,FALSE)) -> Modelo Conceptual | U13: {=(INDEX('Ontology and concepts per UC'!$G$2:$I$46,MATCH($S13,'Ontology and concepts per UC'!$F$2:$F$46,0),MATCH(LEFT($A13,3),'Ontology and concepts per UC'!$G$1:$I$1,0))=0)} -> FALSE | V13: =COUNTIF(W13:Z13,TRUE)>0 -> FALSE | W13: FALSE | X13: FALSE | Y13: FALSE | Z13: FALSE
A14: UC1-F1-P1-S1-M1 | B14: BTD_Manif_OpticAtrophy | C14: Manifestation | D14: =IF(ISBLANK(C14),0,LEN(C14)-LEN(SUBSTITUTE(C14,";",""))+1) -> 1 | E14: =IF(D14<2,C14,LEFT(C14,FIND(";",C14)-1)) -> Manifestation | F14: =IF(D14<1,FALSE,ISERROR(MATCH(E14,'Ontology and concepts per UC'!$A$2:$A$62,0))) -> FALSE | G14: =IF(D14<2,"",MID(C14,LEN(E14)+3,LEN(C14)-FIND(";",C14)-1)) | H14: =IF(D14<3,G14,LEFT(G14,FIND(";",G14)-1)) | I14: =IF(D14<2,FALSE,ISERROR(MATCH(H14,'Ontology and concepts per UC'!$A$2:$A$62,0))) -> FALSE | J14: =IF(D14<3,"",RIGHT(G14,LEN(G14)-FIND(";",G14)-1)) | K14: =IF(D14<3,FALSE,ISERROR(MATCH(J14,'Ontology and concepts per UC'!$A$2:$A$62,0))) -> FALSE | M14: hasDescription:"Atrofia óptica"; | O14: FALSE | P14: 0 | Q14: 0 | R14: =NOT(ISERROR(SEARCH("hasSource",M14))) -> FALSE | S14: Manifestación: Pérdida de visión | T14: =IF(S14="","",VLOOKUP(S14,'Ontology and concepts per UC'!$F$2:$J$46,5,FALSE)) -> Modelo Conceptual | U14: {=(INDEX('Ontology and concepts per UC'!$G$2:$I$46,MATCH($S14,'Ontology and concepts per UC'!$F$2:$F$46,0),MATCH(LEFT($A14,3),'Ontology and concepts per UC'!$G$1:$I$1,0))=0)} -> FALSE | V14: =COUNTIF(W14:Z14,TRUE)>0 -> FALSE | W14: FALSE | X14: FALSE | Y14: FALSE | Z14: FALSE
A15: UC1-F1-P1-S1-M1 | B15: BTD_Manif_Seizures | C15: Manifestation | D15: =IF(ISBLANK(C15),0,LEN(C15)-LEN(SUBSTITUTE(C15,";",""))+1) -> 1 | E15: =IF(D15<2,C15,LEFT(C15,FIND(";",C15)-1)) -> Manifestation | F15: =IF(D15<1,FALSE,ISERROR(MATCH(E15,'Ontology and concepts per UC'!$A$2:$A$62,0))) -> FALSE | G15: =IF(D15<2,"",MID(C15,LEN(E15)+3,LEN(C15)-FIND(";",C15)-1)) | H15: =IF(D15<3,G15,LEFT(G15,FIND(";",G15)-1)) | I15: =IF(D15<2,FALSE,ISERROR(MATCH(H15,'Ontology and concepts per UC'!$A$2:$A$62,0))) -> FALSE | J15: =IF(D15<3,"",RIGHT(G15,LEN(G15)-FIND(";",G15)-1)) | K15: =IF(D15<3,FALSE,ISERROR(MATCH(J15,'Ontology and concepts per UC'!$A$2:$A$62,0))) -> FALSE | M15: hasDescription:"Convulsiones refractarias a tratamiento anticonvulsivo"; | O15: FALSE | P15: 0 | Q15: 0 | R15: =NOT(ISERROR(SEARCH("hasSource",M15))) -> FALSE | S15: Manifestación: Convulsiones | T15: =IF(S15="","",VLOOKUP(S15,'Ontology and concepts per UC'!$F$2:$J$46,5,FALSE)) -> Modelo Conceptual | U15: {=(INDEX('Ontology and concepts per UC'!$G$2:$I$46,MATCH($S15,'Ontology and concepts per UC'!$F$2:$F$46,0),MATCH(LEFT($A15,3),'Ontology and concepts per UC'!$G$1:$I$1,0))=0)} -> FALSE | V15: =COUNTIF(W15:Z15,TRUE)>0 -> FALSE | W15: FALSE | X15: FALSE | Y15: FALSE | Z15: FALSE
A16: UC1-F1-P1-S1-M1 | B16: BTD_Manif_SkinProblems | C16: Manifestation | D16: =IF(ISBLANK(C16),0,LEN(C16)-LEN(SUBSTITUTE(C16,";",""))+1) -> 1 | E16: =IF(D16<2,C16,LEFT(C16,FIND(";",C16)-1)) -> Manifestation | F16: =IF(D16<1,FALSE,ISERROR(MATCH(E16,'Ontology and concepts per UC'!$A$2:$A$62,0))) -> FALSE | G16: =IF(D16<2,"",MID(C16,LEN(E16)+3,LEN(C16)-FIND(";",C16)-1)) | H16: =IF(D16<3,G16,LEFT(G16,FIND(";",G16)-1)) | I16: =IF(D16<2,FALSE,ISERROR(MATCH(H16,'Ontology and concepts per UC'!$A$2:$A$62,0))) -> FALSE | J16: =IF(D16<3,"",RIGHT(G16,LEN(G16)-FIND(";",G16)-1)) | K16: =IF(D16<3,FALSE,ISERROR(MATCH(J16,'Ontology and concepts per UC'!$A$2:$A$62,0))) -> FALSE | M16: hasDescription:"Problemas cutáneos (erupciones, alopecia)"; | O16: FALSE | P16: 0 | Q16: 0 | R16: =NOT(ISERROR(SEARCH("hasSource",M16))) -> FALSE | S16: Manifestación: Problemas en la piel | T16: =IF(S16="","",VLOOKUP(S16,'Ontology and concepts per UC'!$F$2:$J$46,5,FALSE)) -> Modelo Conceptual | U16: {=(INDEX('Ontology and concepts per UC'!$G$2:$I$46,MATCH($S16,'Ontology and concepts per UC'!$F$2:$F$46,0),MATCH(LEFT($A16,3),'Ontology and concepts per UC'!$G$1:$I$1,0))=0)} -> FALSE | V16: =COUNTIF(W16:Z16,TRUE)>0 -> FALSE | W16: FALSE | X16: FALSE | Y16: FALSE | Z16: FALSE
A17: UC1-F1-P1-S1-M1 | B17: BTD_Manif_DevelopmentalDelay_Prob_LateTraeatment | C17: Parameter | D17: =IF(ISBLANK(C17),0,LEN(C17)-LEN(SUBSTITUTE(C17,";",""))+1) -> 1 | E17: =IF(D17<2,C17,LEFT(C17,FIND(";",C17)-1)) -> Parameter | F17: =IF(D17<1,FALSE,ISERROR(MATCH(E17,'Ontology and concepts per UC'!$A$2:$A$62,0))) -> FALSE | G17: =IF(D17<2,"",MID(C17,LEN(E17)+3,LEN(C17)-FIND(";",C17)-1)) | H17: =IF(D17<3,G17,LEFT(G17,FIND(";",G17)-1)) | I17: =IF(D17<2,FALSE,ISERROR(MATCH(H17,'Ontology and concepts per UC'!$A$2:$A$62,0))) -> FALSE | J17: =IF(D17<3,"",RIGHT(G17,LEN(G17)-FIND(";",G17)-1)) | K17: =IF(D17<3,FALSE,ISERROR(MATCH(J17,'Ontology and concepts per UC'!$A$2:$A$62,0))) -> FALSE | M17: hasSource:"Moslinger D et al. Clinical and neuropsychological outcome in 33 patients with biotinidase deficiency ascertained by nationwide newborn screening and family studies in Austria. Eur J Pediatr 2001;160:277-282"; hasDescription:"Probabilidad de retraso del desarrollo persistente con tratamiento tardío"; hasExpectedValue:"0.27"; | O17: FALSE | P17: 0 | Q17: 0 | R17: =NOT(ISERROR(SEARCH("hasSource",M17))) -> TRUE | S17: Riesgo: Retraso mental | T17: =IF(S17="","",VLOOKUP(S17,'Ontology and concepts per UC'!$F$2:$J$46,5,FALSE)) -> Parámetros de progresión | U17: {=(INDEX('Ontology and concepts per UC'!$G$2:$I$46,MATCH($S17,'Ontology and concepts per UC'!$F$2:$F$46,0),MATCH(LEFT($A17,3),'Ontology and concepts per UC'!$G$1:$I$1,0))=0)} -> FALSE | V17: =COUNTIF(W17:Z17,TRUE)>0 -> TRUE | W17: FALSE | X17: FALSE | Y17: FALSE | Z17: TRUE | AA17: Value not found in source
A18: UC1-F1-P1-S1-M1 | B18: BTD_Manif_DevelopmentalDelay_Prob_WithoutTreatment | C18: Parameter | D18: =IF(ISBLANK(C18),0,LEN(C18)-LEN(SUBSTITUTE(C18,";",""))+1) -> 1 | E18: =IF(D18<2,C18,LEFT(C18,FIND(";",C18)-1)) -> Parameter | F18: =IF(D18<1,FALSE,ISERROR(MATCH(E18,'Ontology and concepts per UC'!$A$2:$A$62,0))) -> FALSE | G18: =IF(D18<2,"",MID(C18,LEN(E18)+3,LEN(C18)-FIND(";",C18)-1)) | H18: =IF(D18<3,G18,LEFT(G18,FIND(";",G18)-1)) | I18: =IF(D18<2,FALSE,ISERROR(MATCH(H18,'Ontology and concepts per UC'!$A$2:$A$62,0))) -> FALSE | J18: =IF(D18<3,"",RIGHT(G18,LEN(G18)-FIND(";",G18)-1)) | K18: =IF(D18<3,FALSE,ISERROR(MATCH(J18,'Ontology and concepts per UC'!$A$2:$A$62,0))) -> FALSE | M18: hasDescription:"Probabilidad de desarrollar retraso del desarrollo sin tratamiento"; hasSource:"Moslinger D et al. Clinical and neuropsychological outcome in 33 patients with biotinidase deficiency ascertained by nationwide newborn screening and family studies in Austria. Eur J Pediatr 2001;160:277-282"; hasExpectedValue:"0.60"; | O18: FALSE | P18: 0 | Q18: 0 | R18: =NOT(ISERROR(SEARCH("hasSource",M18))) -> TRUE | S18: Riesgo: Retraso mental | T18: =IF(S18="","",VLOOKUP(S18,'Ontology and concepts per UC'!$F$2:$J$46,5,FALSE)) -> Parámetros de progresión | U18: {=(INDEX('Ontology and concepts per UC'!$G$2:$I$46,MATCH($S18,'Ontology and concepts per UC'!$F$2:$F$46,0),MATCH(LEFT($A18,3),'Ontology and concepts per UC'!$G$1:$I$1,0))=0)} -> FALSE | V18: =COUNTIF(W18:Z18,TRUE)>0 -> TRUE | W18: FALSE | X18: FALSE | Y18: FALSE | Z18: TRUE | AA18: Value not found in source
A19: UC1-F1-P1-S1-M1 | B19: BTD_Manif_HearingLoss_Prob_LateTraeatment | C19: Parameter | D19: =IF(ISBLANK(C19),0,LEN(C19)-LEN(SUBSTITUTE(C19,";",""))+1) -> 1 | E19: =IF(D19<2,C19,LEFT(C19,FIND(";",C19)-1)) -> Parameter | F19: =IF(D19<1,FALSE,ISERROR(MATCH(E19,'Ontology and concepts per UC'!$A$2:$A$62,0))) -> FALSE | G19: =IF(D19<2,"",MID(C19,LEN(E19)+3,LEN(C19)-FIND(";",C19)-1)) | H19: =IF(D19<3,G19,LEFT(G19,FIND(";",G19)-1)) | I19: =IF(D19<2,FALSE,ISERROR(MATCH(H19,'Ontology and concepts per UC'!$A$2:$A$62,0))) -> FALSE | J19: =IF(D19<3,"",RIGHT(G19,LEN(G19)-FIND(";",G19)-1)) | K19: =IF(D19<3,FALSE,ISERROR(MATCH(J19,'Ontology and concepts per UC'!$A$2:$A$62,0))) -> FALSE | M19: hasExpectedValue:"0.36"; hasDescription:"Probabilidad de pérdida auditiva persistente con tratamiento tardío"; hasSource:"Weber P et al. Outcome in patients with profound biotinidase deficiency: relevance of newborn screening. Dev Med Child Neurol 2004;46:481-4"; | O19: FALSE | P19: 0 | Q19: 0 | R19: =NOT(ISERROR(SEARCH("hasSource",M19))) -> TRUE | S19: Riesgo: Problemas de audición | T19: =IF(S19="","",VLOOKUP(S19,'Ontology and concepts per UC'!$F$2:$J$46,5,FALSE)) -> Parámetros de progresión | U19: {=(INDEX('Ontology and concepts per UC'!$G$2:$I$46,MATCH($S19,'Ontology and concepts per UC'!$F$2:$F$46,0),MATCH(LEFT($A19,3),'Ontology and concepts per UC'!$G$1:$I$1,0))=0)} -> FALSE | V19: =COUNTIF(W19:Z19,TRUE)>0 -> TRUE | W19: FALSE | X19: FALSE | Y19: FALSE | Z19: TRUE | AA19: Value not found in source
A20: UC1-F1-P1-S1-M1 | B20: BTD_Manif_HearingLoss_Prob_WithoutTreatment | C20: Parameter | D20: =IF(ISBLANK(C20),0,LEN(C20)-LEN(SUBSTITUTE(C20,";",""))+1) -> 1 | E20: =IF(D20<2,C20,LEFT(C20,FIND(";",C20)-1)) -> Parameter | F20: =IF(D20<1,FALSE,ISERROR(MATCH(E20,'Ontology and concepts per UC'!$A$2:$A$62,0))) -> FALSE | G20: =IF(D20<2,"",MID(C20,LEN(E20)+3,LEN(C20)-FIND(";",C20)-1)) | H20: =IF(D20<3,G20,LEFT(G20,FIND(";",G20)-1)) | I20: =IF(D20<2,FALSE,ISERROR(MATCH(H20,'Ontology and concepts per UC'!$A$2:$A$62,0))) -> FALSE | J20: =IF(D20<3,"",RIGHT(G20,LEN(G20)-FIND(";",G20)-1)) | K20: =IF(D20<3,FALSE,ISERROR(MATCH(J20,'Ontology and concepts per UC'!$A$2:$A$62,0))) -> FALSE | M20: hasDescription:"Probabilidad de desarrollar pérdida auditiva sin tratamiento"; hasExpectedValue:"0.55"; hasExpectedValue:"0.75"; hasSource:"Wolf B, Spencer R, Gleason T. Hearing loss is a common feature of symptomatic children with profound biotinidase deficiency. J Pediatr 2002;140:242-246"; hasSource:"Wolf B et al. Hearing loss is a common feature... J Pediatr 2002;140:242-246"; | O20: FALSE | P20: 0 | Q20: 0 | R20: =NOT(ISERROR(SEARCH("hasSource",M20))) -> TRUE | S20: Riesgo: Problemas de audición | T20: =IF(S20="","",VLOOKUP(S20,'Ontology and concepts per UC'!$F$2:$J$46,5,FALSE)) -> Parámetros de progresión | U20: {=(INDEX('Ontology and concepts per UC'!$G$2:$I$46,MATCH($S20,'Ontology and concepts per UC'!$F$2:$F$46,0),MATCH(LEFT($A20,3),'Ontology and concepts per UC'!$G$1:$I$1,0))=0)} -> FALSE | V20: =COUNTIF(W20:Z20,TRUE)>0 -> TRUE | W20: FALSE | X20: TRUE | Y20: FALSE | Z20: TRUE | AA20: Dataproperty used twice; one of them is incorrect
A21: UC1-F1-P1-S1-M1 | B21: BTD_Manif_OpticAtrophy_Prob_LateTraeatment | C21: Parameter | D21: =IF(ISBLANK(C21),0,LEN(C21)-LEN(SUBSTITUTE(C21,";",""))+1) -> 1 | E21: =IF(D21<2,C21,LEFT(C21,FIND(";",C21)-1)) -> Parameter | F21: =IF(D21<1,FALSE,ISERROR(MATCH(E21,'Ontology and concepts per UC'!$A$2:$A$62,0))) -> FALSE | G21: =IF(D21<2,"",MID(C21,LEN(E21)+3,LEN(C21)-FIND(";",C21)-1)) | H21: =IF(D21<3,G21,LEFT(G21,FIND(";",G21)-1)) | I21: =IF(D21<2,FALSE,ISERROR(MATCH(H21,'Ontology and concepts per UC'!$A$2:$A$62,0))) -> FALSE | J21: =IF(D21<3,"",RIGHT(G21,LEN(G21)-FIND(";",G21)-1)) | K21: =IF(D21<3,FALSE,ISERROR(MATCH(J21,'Ontology and concepts per UC'!$A$2:$A$62,0))) -> FALSE | M21: hasDescription:"Probabilidad de atrofia óptica persistente con tratamiento tardío"; hasSource:"Salbert BA, Astruc J, Wolf B. Ophthalmologic findings in biotinidase deficiency. Ophthalmologica 1993;206:177-181"; hasExpectedValue:"0.20"; | O21: FALSE | P21: 0 | Q21: 0 | R21: =NOT(ISERROR(SEARCH("hasSource",M21))) -> TRUE | S21: Riesgo: Pérdida de visión | T21: =IF(S21="","",VLOOKUP(S21,'Ontology and concepts per UC'!$F$2:$J$46,5,FALSE)) -> Parámetros de progresión | U21: {=(INDEX('Ontology and concepts per UC'!$G$2:$I$46,MATCH($S21,'Ontology and concepts per UC'!$F$2:$F$46,0),MATCH(LEFT($A21,3),'Ontology and concepts per UC'!$G$1:$I$1,0))=0)} -> FALSE | V21: =COUNTIF(W21:Z21,TRUE)>0 -> TRUE | W21: FALSE | X21: FALSE | Y21: FALSE | Z21: TRUE | AA21: Value not found in source
A22: UC1-F1-P1-S1-M1 | B22: BTD_Manif_OpticAtrophy_Prob_WithoutTreatment | C22: Parameter | D22: =IF(ISBLANK(C22),0,LEN(C22)-LEN(SUBSTITUTE(C22,";",""))+1) -> 1 | E22: =IF(D22<2,C22,LEFT(C22,FIND(";",C22)-1)) -> Parameter | F22: =IF(D22<1,FALSE,ISERROR(MATCH(E22,'Ontology and concepts per UC'!$A$2:$A$62,0))) -> FALSE | G22: =IF(D22<2,"",MID(C22,LEN(E22)+3,LEN(C22)-FIND(";",C22)-1)) | H22: =IF(D22<3,G22,LEFT(G22,FIND(";",G22)-1)) | I22: =IF(D22<2,FALSE,ISERROR(MATCH(H22,'Ontology and concepts per UC'!$A$2:$A$62,0))) -> FALSE | J22: =IF(D22<3,"",RIGHT(G22,LEN(G22)-FIND(";",G22)-1)) | K22: =IF(D22<3,FALSE,ISERROR(MATCH(J22,'Ontology and concepts per UC'!$A$2:$A$62,0))) -> FALSE | M22: hasDescription:"Probabilidad de desarrollar atrofia óptica sin tratamiento"; hasExpectedValue:"0.30"; hasSource:"Salbert BA, Astruc J, Wolf B. Ophthalmologic findings in biotinidase deficiency. Ophthalmologica 1993;206:177-181"; | O22: FALSE | P22: 0 | Q22: 0 | R22: =NOT(ISERROR(SEARCH("hasSource",M22))) -> TRUE | S22: Riesgo: Pérdida de visión | T22: =IF(S22="","",VLOOKUP(S22,'Ontology and concepts per UC'!$F$2:$J$46,5,FALSE)) -> Parámetros de progresión | U22: {=(INDEX('Ontology and concepts per UC'!$G$2:$I$46,MATCH($S22,'Ontology and concepts per UC'!$F$2:$F$46,0),MATCH(LEFT($A22,3),'Ontology and concepts per UC'!$G$1:$I$1,0))=0)} -> FALSE | V22: =COUNTIF(W22:Z22,TRUE)>0 -> TRUE | W22: FALSE | X22: FALSE | Y22: FALSE | Z22: TRUE | AA22: Value not found in source
A23: UC1-F1-P1-S1-M1 | B23: BTD_Manif_Seizures_Prob_WithoutTreatment | C23: Parameter | D23: =IF(ISBLANK(C23),0,LEN(C23)-LEN(SUBSTITUTE(C23,";",""))+1) -> 1 | E23: =IF(D23<2,C23,LEFT(C23,FIND(";",C23)-1)) -> Parameter | F23: =IF(D23<1,FALSE,ISERROR(MATCH(E23,'Ontology and concepts per UC'!$A$2:$A$62,0))) -> FALSE | G23: =IF(D23<2,"",MID(C23,LEN(E23)+3,LEN(C23)-FIND(";",C23)-1)) | H23: =IF(D23<3,G23,LEFT(G23,FIND(";",G23)-1)) | I23: =IF(D23<2,FALSE,ISERROR(MATCH(H23,'Ontology and concepts per UC'!$A$2:$A$62,0))) -> FALSE | J23: =IF(D23<3,"",RIGHT(G23,LEN(G23)-FIND(";",G23)-1)) | K23: =IF(D23<3,FALSE,ISERROR(MATCH(J23,'Ontology and concepts per UC'!$A$2:$A$62,0))) -> FALSE | M23: hasExpectedValue:"0.70"; hasSource:"Weber P et al. Outcome in patients with profound biotinidase deficiency: relevance of newborn screening. Dev Med Child Neurol 2004;46:481-4"; hasDescription:"Probabilidad de desarrollar convulsiones sin tratamiento"; | O23: FALSE | P23: 0 | Q23: 0 | R23: =NOT(ISERROR(SEARCH("hasSource",M23))) -> TRUE | S23: Riesgo: Convulsiones | T23: =IF(S23="","",VLOOKUP(S23,'Ontology and concepts per UC'!$F$2:$J$46,5,FALSE)) -> Parámetros de progresión | U23: {=(INDEX('Ontology and concepts per UC'!$G$2:$I$46,MATCH($S23,'Ontology and concepts per UC'!$F$2:$F$46,0),MATCH(LEFT($A23,3),'Ontology and concepts per UC'!$G$1:$I$1,0))=0)} -> FALSE | V23: =COUNTIF(W23:Z23,TRUE)>0 -> TRUE | W23: FALSE | X23: FALSE | Y23: FALSE | Z23: TRUE | AA23: Value not found in source
A24: UC1-F1-P1-S1-M1 | B24: BTD_Screening_Specificity | C24: Parameter | D24: =IF(ISBLANK(C24),0,LEN(C24)-LEN(SUBSTITUTE(C24,";",""))+1) -> 1 | E24: =IF(D24<2,C24,LEFT(C24,FIND(";",C24)-1)) -> Parameter | F24: =IF(D24<1,FALSE,ISERROR(MATCH(E24,'Ontology and concepts per UC'!$A$2:$A$62,0))) -> FALSE | G24: =IF(D24<2,"",MID(C24,LEN(E24)+3,LEN(C24)-FIND(";",C24)-1)) | H24: =IF(D24<3,G24,LEFT(G24,FIND(";",G24)-1)) | I24: =IF(D24<2,FALSE,ISERROR(MATCH(H24,'Ontology and concepts per UC'!$A$2:$A$62,0))) -> FALSE | J24: =IF(D24<3,"",RIGHT(G24,LEN(G24)-FIND(";",G24)-1)) | K24: =IF(D24<3,FALSE,ISERROR(MATCH(J24,'Ontology and concepts per UC'!$A$2:$A$62,0))) -> FALSE | M24: hasExpectedValue:"0.998"; hasDescription:"Especificidad del cribado neonatal para la deficiencia de biotinidasa"; | O24: FALSE | P24: 0 | Q24: 0 | R24: =NOT(ISERROR(SEARCH("hasSource",M24))) -> FALSE | S24: Especificidad | T24: =IF(S24="","",VLOOKUP(S24,'Ontology and concepts per UC'!$F$2:$J$46,5,FALSE)) -> Parámetros de intervención | U24: {=(INDEX('Ontology and concepts per UC'!$G$2:$I$46,MATCH($S24,'Ontology and concepts per UC'!$F$2:$F$46,0),MATCH(LEFT($A24,3),'Ontology and concepts per UC'!$G$1:$I$1,0))=0)} -> FALSE | V24: =COUNTIF(W24:Z24,TRUE)>0 -> FALSE | W24: FALSE | X24: FALSE | Y24: FALSE | Z24: FALSE
A25: UC1-F1-P1-S1-M1 | B25: BTD_Screening_Sensitivity | C25: Parameter; DeterministicParameter | D25: =IF(ISBLANK(C25),0,LEN(C25)-LEN(SUBSTITUTE(C25,";",""))+1) -> 2 | E25: =IF(D25<2,C25,LEFT(C25,FIND(";",C25)-1)) -> Parameter | F25: =IF(D25<1,FALSE,ISERROR(MATCH(E25,'Ontology and concepts per UC'!$A$2:$A$62,0))) -> FALSE | G25: =IF(D25<2,"",MID(C25,LEN(E25)+3,LEN(C25)-FIND(";",C25)-1)) -> DeterministicParameter | H25: =IF(D25<3,G25,LEFT(G25,FIND(";",G25)-1)) -> DeterministicParameter | I25: =IF(D25<2,FALSE,ISERROR(MATCH(H25,'Ontology and concepts per UC'!$A$2:$A$62,0))) -> FALSE | J25: =IF(D25<3,"",RIGHT(G25,LEN(G25)-FIND(";",G25)-1)) | K25: =IF(D25<3,FALSE,ISERROR(MATCH(J25,'Ontology and concepts per UC'!$A$2:$A$62,0))) -> FALSE | M25: hasExpectedValue:"0.99"; hasDescription:"Sensibilidad del cribado neonatal para la deficiencia de biotinidasa"; | O25: FALSE | P25: 0 | Q25: 0 | R25: =NOT(ISERROR(SEARCH("hasSource",M25))) -> FALSE | S25: Caracterización cribado | T25: =IF(S25="","",VLOOKUP(S25,'Ontology and concepts per UC'!$F$2:$J$46,5,FALSE)) -> Parámetros de intervención | U25: {=(INDEX('Ontology and concepts per UC'!$G$2:$I$46,MATCH($S25,'Ontology and concepts per UC'!$F$2:$F$46,0),MATCH(LEFT($A25,3),'Ontology and concepts per UC'!$G$1:$I$1,0))=0)} -> FALSE | V25: =COUNTIF(W25:Z25,TRUE)>0 -> FALSE | W25: FALSE | X25: FALSE | Y25: FALSE | Z25: FALSE
A26: UC1-F1-P1-S1-M1 | B26: BTD_Population_Newborns_ES | C26: Population | D26: =IF(ISBLANK(C26),0,LEN(C26)-LEN(SUBSTITUTE(C26,";",""))+1) -> 1 | E26: =IF(D26<2,C26,LEFT(C26,FIND(";",C26)-1)) -> Population | F26: =IF(D26<1,FALSE,ISERROR(MATCH(E26,'Ontology and concepts per UC'!$A$2:$A$62,0))) -> FALSE | G26: =IF(D26<2,"",MID(C26,LEN(E26)+3,LEN(C26)-FIND(";",C26)-1)) | H26: =IF(D26<3,G26,LEFT(G26,FIND(";",G26)-1)) | I26: =IF(D26<2,FALSE,ISERROR(MATCH(H26,'Ontology and concepts per UC'!$A$2:$A$62,0))) -> FALSE | J26: =IF(D26<3,"",RIGHT(G26,LEN(G26)-FIND(";",G26)-1)) | K26: =IF(D26<3,FALSE,ISERROR(MATCH(J26,'Ontology and concepts per UC'!$A$2:$A$62,0))) -> FALSE | L26: hasSubpopulation:GeneralPopulation; | M26: hasDescription:"Recién nacidos en España durante un año natural"; hasMaxAge:"1"; hasMinAge:"0"; hasGeographicalContext:"España"; | O26: FALSE | P26: 0 | Q26: 0 | R26: =NOT(ISERROR(SEARCH("hasSource",M26))) -> FALSE | S26: Población | T26: =IF(S26="","",VLOOKUP(S26,'Ontology and concepts per UC'!$F$2:$J$46,5,FALSE)) -> Modelo Conceptual | U26: {=(INDEX('Ontology and concepts per UC'!$G$2:$I$46,MATCH($S26,'Ontology and concepts per UC'!$F$2:$F$46,0),MATCH(LEFT($A26,3),'Ontology and concepts per UC'!$G$1:$I$1,0))=0)} -> FALSE | V26: =COUNTIF(W26:Z26,TRUE)>0 -> TRUE | W26: TRUE | X26: FALSE | Y26: FALSE | Z26: FALSE | AA26: Makes reference to an undefined individual
A27: UC1-F1-P1-S1-M1 | B27: BTD_Disease | C27: RareDisease; Disease | D27: =IF(ISBLANK(C27),0,LEN(C27)-LEN(SUBSTITUTE(C27,";",""))+1) -> 2 | E27: =IF(D27<2,C27,LEFT(C27,FIND(";",C27)-1)) -> RareDisease | F27: =IF(D27<1,FALSE,ISERROR(MATCH(E27,'Ontology and concepts per UC'!$A$2:$A$62,0))) -> FALSE | G27: =IF(D27<2,"",MID(C27,LEN(E27)+3,LEN(C27)-FIND(";",C27)-1)) -> Disease | H27: =IF(D27<3,G27,LEFT(G27,FIND(";",G27)-1)) -> Disease | I27: =IF(D27<2,FALSE,ISERROR(MATCH(H27,'Ontology and concepts per UC'!$A$2:$A$62,0))) -> FALSE | J27: =IF(D27<3,"",RIGHT(G27,LEN(G27)-FIND(";",G27)-1)) | K27: =IF(D27<3,FALSE,ISERROR(MATCH(J27,'Ontology and concepts per UC'!$A$2:$A$62,0))) -> FALSE | L27: hasFollowUpStrategy:BTD_FollowUp_AnnualMonitoring; hasDisutilityCombinationMethod:AdditiveDisutility; hasEpidemiologicalParameter:BTD_Incidence; | M27: hasDescription:"Deficiencia de biotinidasa"; hasSource:"Wolf B. Disorders of biotin metabolism. In: Scriver CR et al., eds. The metabolic and molecular bases of inherited disease, 7th ed. 2001"; | O27: FALSE | P27: 0 | Q27: 1 | R27: =NOT(ISERROR(SEARCH("hasSource",M27))) -> TRUE | S27: Enfermedad | T27: =IF(S27="","",VLOOKUP(S27,'Ontology and concepts per UC'!$F$2:$J$46,5,FALSE)) -> Modelo Conceptual | U27: {=(INDEX('Ontology and concepts per UC'!$G$2:$I$46,MATCH($S27,'Ontology and concepts per UC'!$F$2:$F$46,0),MATCH(LEFT($A27,3),'Ontology and concepts per UC'!$G$1:$I$1,0))=0)} -> FALSE | V27: =COUNTIF(W27:Z27,TRUE)>0 -> TRUE | W27: TRUE | X27: FALSE | Y27: FALSE | Z27: FALSE | AA27: ObjectProp 'hasDisutilityCombinationMethod' undefined
A28: UC1-F1-P1-S1-M1 | B28: BTD_Incidence | C28: SecondOrderUncertaintyParameter; EpidemiologicalParameter | D28: =IF(ISBLANK(C28),0,LEN(C28)-LEN(SUBSTITUTE(C28,";",""))+1) -> 2 | E28: =IF(D28<2,C28,LEFT(C28,FIND(";",C28)-1)) -> SecondOrderUncertaintyParameter | F28: =IF(D28<1,FALSE,ISERROR(MATCH(E28,'Ontology and concepts per UC'!$A$2:$A$62,0))) -> FALSE | G28: =IF(D28<2,"",MID(C28,LEN(E28)+3,LEN(C28)-FIND(";",C28)-1)) -> EpidemiologicalParameter | H28: =IF(D28<3,G28,LEFT(G28,FIND(";",G28)-1)) -> EpidemiologicalParameter | I28: =IF(D28<2,FALSE,ISERROR(MATCH(H28,'Ontology and concepts per UC'!$A$2:$A$62,0))) -> FALSE | J28: =IF(D28<3,"",RIGHT(G28,LEN(G28)-FIND(";",G28)-1)) | K28: =IF(D28<3,FALSE,ISERROR(MATCH(J28,'Ontology and concepts per UC'!$A$2:$A$62,0))) -> FALSE | M28: hasDescription:"Incidencia de la deficiencia profunda de biotinidasa"; hasSource:"Wolf B. Worldwide survey of neonatal screening for biotinidase deficiency. J Inherit Metab Dis 1991;14:923-927"; hasExpectedValue:"0.0000125"; | O28: FALSE | P28: 0 | Q28: 0 | R28: =NOT(ISERROR(SEARCH("hasSource",M28))) -> TRUE | S28: Prevalencia al nacimiento | T28: =IF(S28="","",VLOOKUP(S28,'Ontology and concepts per UC'!$F$2:$J$46,5,FALSE)) -> Parámetro epidemiológico | U28: {=(INDEX('Ontology and concepts per UC'!$G$2:$I$46,MATCH($S28,'Ontology and concepts per UC'!$F$2:$F$46,0),MATCH(LEFT($A28,3),'Ontology and concepts per UC'!$G$1:$I$1,0))=0)} -> FALSE | V28: =COUNTIF(W28:Z28,TRUE)>0 -> FALSE | W28: FALSE | X28: FALSE | Y28: FALSE | Z28: FALSE
A29: UC1-F1-P1-S1-M1 | B29: BTD_Manif_Combined_U | C29: UtilityParameter | D29: =IF(ISBLANK(C29),0,LEN(C29)-LEN(SUBSTITUTE(C29,";",""))+1) -> 1 | E29: =IF(D29<2,C29,LEFT(C29,FIND(";",C29)-1)) -> UtilityParameter | F29: =IF(D29<1,FALSE,ISERROR(MATCH(E29,'Ontology and concepts per UC'!$A$2:$A$62,0))) -> TRUE | G29: =IF(D29<2,"",MID(C29,LEN(E29)+3,LEN(C29)-FIND(";",C29)-1)) | H29: =IF(D29<3,G29,LEFT(G29,FIND(";",G29)-1)) | I29: =IF(D29<2,FALSE,ISERROR(MATCH(H29,'Ontology and concepts per UC'!$A$2:$A$62,0))) -> FALSE | J29: =IF(D29<3,"",RIGHT(G29,LEN(G29)-FIND(";",G29)-1)) | K29: =IF(D29<3,FALSE,ISERROR(MATCH(J29,'Ontology and concepts per UC'!$A$2:$A$62,0))) -> FALSE | M29: hasDescription:"Desutilidad anual para casos graves con múltiples síntomas"; appliesOneTime:"false"; hasExpectedValue:"0.49"; | O29: FALSE | P29: 1 | Q29: 0 | R29: =NOT(ISERROR(SEARCH("hasSource",M29))) -> FALSE | S29: Utilidad: Otras | T29: =IF(S29="","",VLOOKUP(S29,'Ontology and concepts per UC'!$F$2:$J$46,5,FALSE)) -> Utilidad | U29: {=(INDEX('Ontology and concepts per UC'!$G$2:$I$46,MATCH($S29,'Ontology and concepts per UC'!$F$2:$F$46,0),MATCH(LEFT($A29,3),'Ontology and concepts per UC'!$G$1:$I$1,0))=0)} -> FALSE | V29: =COUNTIF(W29:Z29,TRUE)>0 -> TRUE | W29: TRUE | X29: FALSE | Y29: FALSE | Z29: FALSE | AA29: Class 'UtilityParameter' undefined
A30: UC1-F1-P1-S1-M1 | B30: BTD_Manif_DevelopmentalDelay_U | C30: UtilityParameter | D30: =IF(ISBLANK(C30),0,LEN(C30)-LEN(SUBSTITUTE(C30,";",""))+1) -> 1 | E30: =IF(D30<2,C30,LEFT(C30,FIND(";",C30)-1)) -> UtilityParameter | F30: =IF(D30<1,FALSE,ISERROR(MATCH(E30,'Ontology and concepts per UC'!$A$2:$A$62,0))) -> TRUE | G30: =IF(D30<2,"",MID(C30,LEN(E30)+3,LEN(C30)-FIND(";",C30)-1)) | H30: =IF(D30<3,G30,LEFT(G30,FIND(";",G30)-1)) | I30: =IF(D30<2,FALSE,ISERROR(MATCH(H30,'Ontology and concepts per UC'!$A$2:$A$62,0))) -> FALSE | J30: =IF(D30<3,"",RIGHT(G30,LEN(G30)-FIND(";",G30)-1)) | K30: =IF(D30<3,FALSE,ISERROR(MATCH(J30,'Ontology and concepts per UC'!$A$2:$A$62,0))) -> FALSE | M30: hasExpectedValue:"0.29"; appliesOneTime:"false"; hasDescription:"Desutilidad anual asociada a retraso del desarrollo"; | O30: FALSE | P30: 1 | Q30: 0 | R30: =NOT(ISERROR(SEARCH("hasSource",M30))) -> FALSE | S30: Utilidad: Retraso mental | T30: =IF(S30="","",VLOOKUP(S30,'Ontology and concepts per UC'!$F$2:$J$46,5,FALSE)) -> Utilidad | U30: {=(INDEX('Ontology and concepts per UC'!$G$2:$I$46,MATCH($S30,'Ontology and concepts per UC'!$F$2:$F$46,0),MATCH(LEFT($A30,3),'Ontology and concepts per UC'!$G$1:$I$1,0))=0)} -> FALSE | V30: =COUNTIF(W30:Z30,TRUE)>0 -> TRUE | W30: TRUE | X30: FALSE | Y30: FALSE | Z30: FALSE | AA30: Class 'UtilityParameter' undefined
A31: UC1-F1-P1-S1-M1 | B31: BTD_Manif_HearingLoss_U | C31: UtilityParameter | D31: =IF(ISBLANK(C31),0,LEN(C31)-LEN(SUBSTITUTE(C31,";",""))+1) -> 1 | E31: =IF(D31<2,C31,LEFT(C31,FIND(";",C31)-1)) -> UtilityParameter | F31: =IF(D31<1,FALSE,ISERROR(MATCH(E31,'Ontology and concepts per UC'!$A$2:$A$62,0))) -> TRUE | G31: =IF(D31<2,"",MID(C31,LEN(E31)+3,LEN(C31)-FIND(";",C31)-1)) | H31: =IF(D31<3,G31,LEFT(G31,FIND(";",G31)-1)) | I31: =IF(D31<2,FALSE,ISERROR(MATCH(H31,'Ontology and concepts per UC'!$A$2:$A$62,0))) -> FALSE | J31: =IF(D31<3,"",RIGHT(G31,LEN(G31)-FIND(";",G31)-1)) | K31: =IF(D31<3,FALSE,ISERROR(MATCH(J31,'Ontology and concepts per UC'!$A$2:$A$62,0))) -> FALSE | M31: hasExpectedValue:"0.18"; hasDescription:"Desutilidad anual asociada a pérdida auditiva neurosensorial"; appliesOneTime:"false"; | O31: FALSE | P31: 1 | Q31: 0 | R31: =NOT(ISERROR(SEARCH("hasSource",M31))) -> FALSE | S31: Utilidad: Problemas de audición | T31: =IF(S31="","",VLOOKUP(S31,'Ontology and concepts per UC'!$F$2:$J$46,5,FALSE)) -> Utilidad | U31: {=(INDEX('Ontology and concepts per UC'!$G$2:$I$46,MATCH($S31,'Ontology and concepts per UC'!$F$2:$F$46,0),MATCH(LEFT($A31,3),'Ontology and concepts per UC'!$G$1:$I$1,0))=0)} -> FALSE | V31: =COUNTIF(W31:Z31,TRUE)>0 -> TRUE | W31: TRUE | X31: FALSE | Y31: FALSE | Z31: FALSE | AA31: Class 'UtilityParameter' undefined
A32: UC1-F1-P1-S1-M1 | B32: BTD_Manif_OpticAtrophy_U | C32: UtilityParameter | D32: =IF(ISBLANK(C32),0,LEN(C32)-LEN(SUBSTITUTE(C32,";",""))+1) -> 1 | E32: =IF(D32<2,C32,LEFT(C32,FIND(";",C32)-1)) -> UtilityParameter | F32: =IF(D32<1,FALSE,ISERROR(MATCH(E32,'Ontology and concepts per UC'!$A$2:$A$62,0))) -> TRUE | G32: =IF(D32<2,"",MID(C32,LEN(E32)+3,LEN(C32)-FIND(";",C32)-1)) | H32: =IF(D32<3,G32,LEFT(G32,FIND(";",G32)-1)) | I32: =IF(D32<2,FALSE,ISERROR(MATCH(H32,'Ontology and concepts per UC'!$A$2:$A$62,0))) -> FALSE | J32: =IF(D32<3,"",RIGHT(G32,LEN(G32)-FIND(";",G32)-1)) | K32: =IF(D32<3,FALSE,ISERROR(MATCH(J32,'Ontology and concepts per UC'!$A$2:$A$62,0))) -> FALSE | M32: hasExpectedValue:"0.23"; hasDescription:"Desutilidad anual asociada a atrofia óptica"; appliesOneTime:"false"; | O32: FALSE | P32: 1 | Q32: 0 | R32: =NOT(ISERROR(SEARCH("hasSource",M32))) -> FALSE | S32: Utilidad: Pérdida de visión | T32: =IF(S32="","",VLOOKUP(S32,'Ontology and concepts per UC'!$F$2:$J$46,5,FALSE)) -> Utilidad | U32: {=(INDEX('Ontology and concepts per UC'!$G$2:$I$46,MATCH($S32,'Ontology and concepts per UC'!$F$2:$F$46,0),MATCH(LEFT($A32,3),'Ontology and concepts per UC'!$G$1:$I$1,0))=0)} -> FALSE | V32: =COUNTIF(W32:Z32,TRUE)>0 -> TRUE | W32: TRUE | X32: FALSE | Y32: FALSE | Z32: FALSE | AA32: Class 'UtilityParameter' undefined
A33: UC1-F1-P1-S1-M1 | B33: BTD_Manif_Seizures_U | C33: UtilityParameter | D33: =IF(ISBLANK(C33),0,LEN(C33)-LEN(SUBSTITUTE(C33,";",""))+1) -> 1 | E33: =IF(D33<2,C33,LEFT(C33,FIND(";",C33)-1)) -> UtilityParameter | F33: =IF(D33<1,FALSE,ISERROR(MATCH(E33,'Ontology and concepts per UC'!$A$2:$A$62,0))) -> TRUE | G33: =IF(D33<2,"",MID(C33,LEN(E33)+3,LEN(C33)-FIND(";",C33)-1)) | H33: =IF(D33<3,G33,LEFT(G33,FIND(";",G33)-1)) | I33: =IF(D33<2,FALSE,ISERROR(MATCH(H33,'Ontology and concepts per UC'!$A$2:$A$62,0))) -> FALSE | J33: =IF(D33<3,"",RIGHT(G33,LEN(G33)-FIND(";",G33)-1)) | K33: =IF(D33<3,FALSE,ISERROR(MATCH(J33,'Ontology and concepts per UC'!$A$2:$A$62,0))) -> FALSE | M33: hasDescription:"Desutilidad anual asociada a convulsiones refractarias"; appliesOneTime:"false"; hasExpectedValue:"0.32"; | O33: FALSE | P33: 1 | Q33: 0 | R33: =NOT(ISERROR(SEARCH("hasSource",M33))) -> FALSE | S33: Utilidad: Convulsiones | T33: =IF(S33="","",VLOOKUP(S33,'Ontology and concepts per UC'!$F$2:$J$46,5,FALSE)) -> Utilidad | U33: {=(INDEX('Ontology and concepts per UC'!$G$2:$I$46,MATCH($S33,'Ontology and concepts per UC'!$F$2:$F$46,0),MATCH(LEFT($A33,3),'Ontology and concepts per UC'!$G$1:$I$1,0))=0)} -> FALSE | V33: =COUNTIF(W33:Z33,TRUE)>0 -> TRUE | W33: TRUE | X33: FALSE | Y33: FALSE | Z33: FALSE | AA33: Class 'UtilityParameter' undefined
A34: UC1-F1-P1-S1-M1 | B34: BTD_Normal_U | C34: UtilityParameter | D34: =IF(ISBLANK(C34),0,LEN(C34)-LEN(SUBSTITUTE(C34,";",""))+1) -> 1 | E34: =IF(D34<2,C34,LEFT(C34,FIND(";",C34)-1)) -> UtilityParameter | F34: =IF(D34<1,FALSE,ISERROR(MATCH(E34,'Ontology and concepts per UC'!$A$2:$A$62,0))) -> TRUE | G34: =IF(D34<2,"",MID(C34,LEN(E34)+3,LEN(C34)-FIND(";",C34)-1)) | H34: =IF(D34<3,G34,LEFT(G34,FIND(";",G34)-1)) | I34: =IF(D34<2,FALSE,ISERROR(MATCH(H34,'Ontology and concepts per UC'!$A$2:$A$62,0))) -> FALSE | J34: =IF(D34<3,"",RIGHT(G34,LEN(G34)-FIND(";",G34)-1)) | K34: =IF(D34<3,FALSE,ISERROR(MATCH(J34,'Ontology and concepts per UC'!$A$2:$A$62,0))) -> FALSE | M34: hasDescription:"Utilidad de vida normal sin síntomas"; hasExpectedValue:"1.0"; | O34: FALSE | P34: 1 | Q34: 0 | R34: =NOT(ISERROR(SEARCH("hasSource",M34))) -> FALSE | S34: Población: utilidad | T34: =IF(S34="","",VLOOKUP(S34,'Ontology and concepts per UC'!$F$2:$J$46,5,FALSE)) -> Modelo Conceptual | U34: {=(INDEX('Ontology and concepts per UC'!$G$2:$I$46,MATCH($S34,'Ontology and concepts per UC'!$F$2:$F$46,0),MATCH(LEFT($A34,3),'Ontology and concepts per UC'!$G$1:$I$1,0))=0)} -> FALSE | V34: =COUNTIF(W34:Z34,TRUE)>0 -> TRUE | W34: TRUE | X34: FALSE | Y34: FALSE | Z34: FALSE | AA34: Class 'UtilityParameter' undefined
A35: UC1-F1-P1-S1-M1 | B35: AdditiveDisutility | D35: =IF(ISBLANK(C35),0,LEN(C35)-LEN(SUBSTITUTE(C35,";",""))+1) -> 0 | E35: =IF(D35<2,C35,LEFT(C35,FIND(";",C35)-1)) -> 0 | F35: =IF(D35<1,FALSE,ISERROR(MATCH(E35,'Ontology and concepts per UC'!$A$2:$A$62,0))) -> FALSE | G35: =IF(D35<2,"",MID(C35,LEN(E35)+3,LEN(C35)-FIND(";",C35)-1)) | H35: =IF(D35<3,G35,LEFT(G35,FIND(";",G35)-1)) | I35: =IF(D35<2,FALSE,ISERROR(MATCH(H35,'Ontology and concepts per UC'!$A$2:$A$62,0))) -> FALSE | J35: =IF(D35<3,"",RIGHT(G35,LEN(G35)-FIND(";",G35)-1)) | K35: =IF(D35<3,FALSE,ISERROR(MATCH(J35,'Ontology and concepts per UC'!$A$2:$A$62,0))) -> FALSE | O35: TRUE | P35: 0 | Q35: 0 | R35: =NOT(ISERROR(SEARCH("hasSource",M35))) -> FALSE | S35: Otros | T35: =IF(S35="","",VLOOKUP(S35,'Ontology and concepts per UC'!$F$2:$J$46,5,FALSE)) -> Otros | U35: {=(INDEX('Ontology and concepts per UC'!$G$2:$I$46,MATCH($S35,'Ontology and concepts per UC'!$F$2:$F$46,0),MATCH(LEFT($A35,3),'Ontology and concepts per UC'!$G$1:$I$1,0))=0)} -> TRUE | V35: =COUNTIF(W35:Z35,TRUE)>0 -> TRUE | W35: TRUE | X35: FALSE | Y35: FALSE | Z35: FALSE | AA35: No Class assigned
A36: UC1-F1-P1-S1-M1 | B36: GeneralPopulation | D36: =IF(ISBLANK(C36),0,LEN(C36)-LEN(SUBSTITUTE(C36,";",""))+1) -> 0 | E36: =IF(D36<2,C36,LEFT(C36,FIND(";",C36)-1)) -> 0 | F36: =IF(D36<1,FALSE,ISERROR(MATCH(E36,'Ontology and concepts per UC'!$A$2:$A$62,0))) -> FALSE | G36: =IF(D36<2,"",MID(C36,LEN(E36)+3,LEN(C36)-FIND(";",C36)-1)) | H36: =IF(D36<3,G36,LEFT(G36,FIND(";",G36)-1)) | I36: =IF(D36<2,FALSE,ISERROR(MATCH(H36,'Ontology and concepts per UC'!$A$2:$A$62,0))) -> FALSE | J36: =IF(D36<3,"",RIGHT(G36,LEN(G36)-FIND(";",G36)-1)) | K36: =IF(D36<3,FALSE,ISERROR(MATCH(J36,'Ontology and concepts per UC'!$A$2:$A$62,0))) -> FALSE | O36: TRUE | P36: 0 | Q36: 0 | R36: =NOT(ISERROR(SEARCH("hasSource",M36))) -> FALSE | S36: Población | T36: =IF(S36="","",VLOOKUP(S36,'Ontology and concepts per UC'!$F$2:$J$46,5,FALSE)) -> Modelo Conceptual | U36: {=(INDEX('Ontology and concepts per UC'!$G$2:$I$46,MATCH($S36,'Ontology and concepts per UC'!$F$2:$F$46,0),MATCH(LEFT($A36,3),'Ontology and concepts per UC'!$G$1:$I$1,0))=0)} -> FALSE | V36: =COUNTIF(W36:Z36,TRUE)>0 -> TRUE | W36: TRUE | X36: FALSE | Y36: FALSE | Z36: FALSE | AA36: No Class assigned
A37: UC1-F1-P1-S2-M1 | B37: Manif_Convulsiones | C37: AcuteManifestation | D37: =IF(ISBLANK(C37),0,LEN(C37)-LEN(SUBSTITUTE(C37,";",""))+1) -> 1 | E37: =IF(D37<2,C37,LEFT(C37,FIND(";",C37)-1)) -> AcuteManifestation | F37: =IF(D37<1,FALSE,ISERROR(MATCH(E37,'Ontology and concepts per UC'!$A$2:$A$62,0))) -> FALSE | G37: =IF(D37<2,"",MID(C37,LEN(E37)+3,LEN(C37)-FIND(";",C37)-1)) | H37: =IF(D37<3,G37,LEFT(G37,FIND(";",G37)-1)) | I37: =IF(D37<2,FALSE,ISERROR(MATCH(H37,'Ontology and concepts per UC'!$A$2:$A$62,0))) -> FALSE | J37: =IF(D37<3,"",RIGHT(G37,LEN(G37)-FIND(";",G37)-1)) | K37: =IF(D37<3,FALSE,ISERROR(MATCH(J37,'Ontology and concepts per UC'!$A$2:$A$62,0))) -> FALSE | O37: FALSE | P37: 0 | Q37: 0 | R37: =NOT(ISERROR(SEARCH("hasSource",M37))) -> FALSE | S37: Manifestación: Convulsiones | T37: =IF(S37="","",VLOOKUP(S37,'Ontology and concepts per UC'!$F$2:$J$46,5,FALSE)) -> Modelo Conceptual | U37: {=(INDEX('Ontology and concepts per UC'!$G$2:$I$46,MATCH($S37,'Ontology and concepts per UC'!$F$2:$F$46,0),MATCH(LEFT($A37,3),'Ontology and concepts per UC'!$G$1:$I$1,0))=0)} -> FALSE | V37: =COUNTIF(W37:Z37,TRUE)>0 -> FALSE | W37: FALSE | X37: FALSE | Y37: FALSE | Z37: FALSE
A38: UC1-F1-P1-S2-M1 | B38: Manif_ErupcionCutanea | C38: ChronicManifestation | D38: =IF(ISBLANK(C38),0,LEN(C38)-LEN(SUBSTITUTE(C38,";",""))+1) -> 1 | E38: =IF(D38<2,C38,LEFT(C38,FIND(";",C38)-1)) -> ChronicManifestation | F38: =IF(D38<1,FALSE,ISERROR(MATCH(E38,'Ontology and concepts per UC'!$A$2:$A$62,0))) -> FALSE | G38: =IF(D38<2,"",MID(C38,LEN(E38)+3,LEN(C38)-FIND(";",C38)-1)) | H38: =IF(D38<3,G38,LEFT(G38,FIND(";",G38)-1)) | I38: =IF(D38<2,FALSE,ISERROR(MATCH(H38,'Ontology and concepts per UC'!$A$2:$A$62,0))) -> FALSE | J38: =IF(D38<3,"",RIGHT(G38,LEN(G38)-FIND(";",G38)-1)) | K38: =IF(D38<3,FALSE,ISERROR(MATCH(J38,'Ontology and concepts per UC'!$A$2:$A$62,0))) -> FALSE | O38: FALSE | P38: 0 | Q38: 0 | R38: =NOT(ISERROR(SEARCH("hasSource",M38))) -> FALSE | S38: Manifestación: Problemas en la piel | T38: =IF(S38="","",VLOOKUP(S38,'Ontology and concepts per UC'!$F$2:$J$46,5,FALSE)) -> Modelo Conceptual | U38: {=(INDEX('Ontology and concepts per UC'!$G$2:$I$46,MATCH($S38,'Ontology and concepts per UC'!$F$2:$F$46,0),MATCH(LEFT($A38,3),'Ontology and concepts per UC'!$G$1:$I$1,0))=0)} -> FALSE | V38: =COUNTIF(W38:Z38,TRUE)>0 -> FALSE | W38: FALSE | X38: FALSE | Y38: FALSE | Z38: FALSE
A39: UC1-F1-P1-S2-M1 | B39: CosteCribadoUnitario | C39: Cost | D39: =IF(ISBLANK(C39),0,LEN(C39)-LEN(SUBSTITUTE(C39,";",""))+1) -> 1 | E39: =IF(D39<2,C39,LEFT(C39,FIND(";",C39)-1)) -> Cost | F39: =IF(D39<1,FALSE,ISERROR(MATCH(E39,'Ontology and concepts per UC'!$A$2:$A$62,0))) -> FALSE | G39: =IF(D39<2,"",MID(C39,LEN(E39)+3,LEN(C39)-FIND(";",C39)-1)) | H39: =IF(D39<3,G39,LEFT(G39,FIND(";",G39)-1)) | I39: =IF(D39<2,FALSE,ISERROR(MATCH(H39,'Ontology and concepts per UC'!$A$2:$A$62,0))) -> FALSE | J39: =IF(D39<3,"",RIGHT(G39,LEN(G39)-FIND(";",G39)-1)) | K39: =IF(D39<3,FALSE,ISERROR(MATCH(J39,'Ontology and concepts per UC'!$A$2:$A$62,0))) -> FALSE | M39: hasExpectedValue:"25.5"; | O39: FALSE | P39: 0 | Q39: 0 | R39: =NOT(ISERROR(SEARCH("hasSource",M39))) -> FALSE | S39: Coste cribado | T39: =IF(S39="","",VLOOKUP(S39,'Ontology and concepts per UC'!$F$2:$J$46,5,FALSE)) -> Coste | U39: {=(INDEX('Ontology and concepts per UC'!$G$2:$I$46,MATCH($S39,'Ontology and concepts per UC'!$F$2:$F$46,0),MATCH(LEFT($A39,3),'Ontology and concepts per UC'!$G$1:$I$1,0))=0)} -> FALSE | V39: =COUNTIF(W39:Z39,TRUE)>0 -> TRUE | W39: FALSE | X39: FALSE | Y39: FALSE | Z39: TRUE | AA39: Unsuitable value for property
A40: UC1-F1-P1-S2-M1 | B40: CosteDiagnostico | C40: Cost | D40: =IF(ISBLANK(C40),0,LEN(C40)-LEN(SUBSTITUTE(C40,";",""))+1) -> 1 | E40: =IF(D40<2,C40,LEFT(C40,FIND(";",C40)-1)) -> Cost | F40: =IF(D40<1,FALSE,ISERROR(MATCH(E40,'Ontology and concepts per UC'!$A$2:$A$62,0))) -> FALSE | G40: =IF(D40<2,"",MID(C40,LEN(E40)+3,LEN(C40)-FIND(";",C40)-1)) | H40: =IF(D40<3,G40,LEFT(G40,FIND(";",G40)-1)) | I40: =IF(D40<2,FALSE,ISERROR(MATCH(H40,'Ontology and concepts per UC'!$A$2:$A$62,0))) -> FALSE | J40: =IF(D40<3,"",RIGHT(G40,LEN(G40)-FIND(";",G40)-1)) | K40: =IF(D40<3,FALSE,ISERROR(MATCH(J40,'Ontology and concepts per UC'!$A$2:$A$62,0))) -> FALSE | M40: hasExpectedValue:"150.0"; | O40: FALSE | P40: 0 | Q40: 0 | R40: =NOT(ISERROR(SEARCH("hasSource",M40))) -> FALSE | S40: Coste de diagnóstico | T40: =IF(S40="","",VLOOKUP(S40,'Ontology and concepts per UC'!$F$2:$J$46,5,FALSE)) -> Coste | U40: {=(INDEX('Ontology and concepts per UC'!$G$2:$I$46,MATCH($S40,'Ontology and concepts per UC'!$F$2:$F$46,0),MATCH(LEFT($A40,3),'Ontology and concepts per UC'!$G$1:$I$1,0))=0)} -> FALSE | V40: =COUNTIF(W40:Z40,TRUE)>0 -> FALSE | W40: FALSE | X40: FALSE | Y40: FALSE | Z40: FALSE
...

Sheet Backup (porsi)
A1: Test ID | B1: URI | C1: Classes | D1: ObjectProperties | E1: DataProperties | F1: Hallucination | G1: Error OWL | H1: Related concept | I1: Group of concepts | J1: Comments
A2: UC1-F1-P1-S1-M1 | B2: #BTD_BiotinTreatment_AnnualCost | C2: CostParameter | E2: #hasDescription: Coste anual del tratamiento con biotina (5-10 mg/día); #hasUnit: EUR; #hasExpectedValue: 730; | F2: FALSE | G2: TRUE | H2: Coste tratamiento | I2: {=IF(H2="","",VLOOKUP(H2,_xludf.HSTACK(#REF!,#REF!),2,FALSE))} -> #NAME?
A3: UC1-F1-P1-S1-M1 | B3: #BTD_DiagnosticTest_Cost | C3: CostParameter | E3: #hasExpectedValue: 150; #hasDescription: Coste de la prueba diagnóstica confirmatoria; | F3: FALSE | G3: TRUE | H3: Coste de diagnóstico | I3: {=IF(H3="","",VLOOKUP(H3,_xludf.HSTACK(#REF!,#REF!),2,FALSE))} -> #NAME?
A4: UC1-F1-P1-S1-M1 | B4: #BTD_Disease | C4: RareDisease, Disease | D4: #hasEpidemiologicalParameter: #BTD_Incidence; #hasDisutilityCombinationMethod: #AdditiveDisutility; #hasFollowUpStrategy: #BTD_FollowUp_AnnualMonitoring; | E4: #hasSource: Wolf B. Disorders of biotin metabolism. In: Scriver CR et al., eds. The metabolic and molecular bases of inherited disease, 7th ed. 2001; #hasDescription: Deficiencia de biotinidasa; | F4: FALSE | G4: FALSE | H4: Enfermedad | I4: {=IF(H4="","",VLOOKUP(H4,_xludf.HSTACK(#REF!,#REF!),2,FALSE))} -> #NAME?
A5: UC1-F1-P1-S1-M1 | B5: #BTD_Disease_Partial | C5: Disease | D5: #isSubtypeOf: #BTD_Disease; | E5: #hasDescription: Deficiencia parcial de biotinidasa (actividad enzimática 10-30% del valor normal); | F5: FALSE | G5: FALSE | I5: {=IF(H5="","",VLOOKUP(H5,_xludf.HSTACK(#REF!,#REF!),2,FALSE))}
A6: UC1-F1-P1-S1-M1 | B6: #BTD_Disease_Profound | C6: Disease | D6: #hasFeature: #BTD_Manif_Hypotonia; #hasFeature: #BTD_Manif_DevelopmentalDelay; #hasFeature: #BTD_Manif_HearingLoss; #hasFeature: #BTD_Manif_SkinProblems; #isSubtypeOf: #BTD_Disease; #hasFeature: #BTD_Manif_OpticAtrophy; #hasFeature: #BTD_Manif_Seizures; | E6: #hasDescription: Deficiencia profunda de biotinidasa (actividad enzimática menor del 10% del valor normal); | F6: FALSE | G6: TRUE | H6: Enfermedad | I6: {=IF(H6="","",VLOOKUP(H6,_xludf.HSTACK(#REF!,#REF!),2,FALSE))} -> #NAME? | J6: Debería haber usado el concepto de Development, pero es coherente. Se inventó el concepto "hasfeature"
A7: UC1-F1-P1-S1-M1 | B7: #BTD_FollowUp_AnnualMonitoring | C7: FollowUpStrategy | F7: FALSE | G7: FALSE | H7: Seguimiento | I7: {=IF(H7="","",VLOOKUP(H7,_xludf.HSTACK(#REF!,#REF!),2,FALSE))} -> #NAME?
A8: UC1-F1-P1-S1-M1 | B8: #BTD_Incidence | C8: EpidemiologicalParameter, SecondOrderUncertaintyParameter | E8: #hasSource: Wolf B. Worldwide survey of neonatal screening for biotinidase deficiency. J Inherit Metab Dis 1991;14:923-927; #hasExpectedValue: 0.0000125; #hasDescription: Incidencia de la deficiencia profunda de biotinidasa; | F8: FALSE | G8: FALSE | H8: Prevalencia al nacimiento | I8: {=IF(H8="","",VLOOKUP(H8,_xludf.HSTACK(#REF!,#REF!),2,FALSE))} -> #NAME?
A9: UC1-F1-P1-S1-M1 | B9: #BTD_Intervention_BiotinTreatment | C9: Intervention | D9: #hasTreatmentCost: #BTD_BiotinTreatment_AnnualCost; | E9: #hasDescription: Tratamiento con biotina oral (5-30 mg/día); | F9: FALSE | G9: FALSE | H9: Tratamiento base | I9: {=IF(H9="","",VLOOKUP(H9,_xludf.HSTACK(#REF!,#REF!),2,FALSE))} -> #NAME? | J9: Identificado erróneamente como intervención
A10: UC1-F1-P1-S1-M1 | B10: #BTD_Intervention_ClinicalDiagnosis | C10: Intervention | E10: #hasDescription: Detección clínica de la deficiencia de biotinidasa tras aparición de síntomas; | F10: FALSE | G10: FALSE | H10: Intervención: No cribado | I10: {=IF(H10="","",VLOOKUP(H10,_xludf.HSTACK(#REF!,#REF!),2,FALSE))} -> #NAME?
A11: UC1-F1-P1-S1-M1 | B11: #BTD_Intervention_Screening | C11: Intervention | D11: #modifies: #BTD_Manif_HearingLoss_Prob_WithoutTreatment; | E11: #hasDescription: Cribado neonatal de la deficiencia de biotinidasa mediante ensayo enzimático o fluorimétrico semicuantitativo; | F11: FALSE | G11: FALSE | H11: Intervención: Cribado | I11: {=IF(H11="","",VLOOKUP(H11,_xludf.HSTACK(#REF!,#REF!),2,FALSE))} -> #NAME?
A12: UC1-F1-P1-S1-M1 | B12: #BTD_Manif_Combined_U | C12: UtilityParameter | E12: #hasDescription: Desutilidad anual para casos graves con múltiples síntomas; #appliesOneTime: false; #hasExpectedValue: 0.49; | F12: FALSE | G12: TRUE | I12: {=IF(H12="","",VLOOKUP(H12,_xludf.HSTACK(#REF!,#REF!),2,FALSE))}
A13: UC1-F1-P1-S1-M1 | B13: #BTD_Manif_DevelopmentalDelay | C13: Manifestation | E13: #hasDescription: Retraso del desarrollo psicomotor; | F13: FALSE | G13: FALSE | H13: Manifestación: Retraso mental | I13: {=IF(H13="","",VLOOKUP(H13,_xludf.HSTACK(#REF!,#REF!),2,FALSE))} -> #NAME?
A14: UC1-F1-P1-S1-M1 | B14: #BTD_Manif_DevelopmentalDelay_Prob_LateTraeatment | C14: Parameter | E14: #hasDescription: Probabilidad de retraso del desarrollo persistente con tratamiento tardío; #hasExpectedValue: 0.27; #hasSource: Moslinger D et al. Clinical and neuropsychological outcome in 33 patients with biotinidase deficiency ascertained by nationwide newborn screening and family studies in Austria. Eur J Pediatr 2001;160:277-282; | F14: TRUE | G14: FALSE | H14: Riesgo: Retraso mental | I14: {=IF(H14="","",VLOOKUP(H14,_xludf.HSTACK(#REF!,#REF!),2,FALSE))} -> #NAME? | J14: No encuentro ese valor en la fuente
A15: UC1-F1-P1-S1-M1 | B15: #BTD_Manif_DevelopmentalDelay_Prob_WithoutTreatment | C15: Parameter | E15: #hasDescription: Probabilidad de desarrollar retraso del desarrollo sin tratamiento; #hasExpectedValue: 0.60; #hasSource: Moslinger D et al. Clinical and neuropsychological outcome in 33 patients with biotinidase deficiency ascertained by nationwide newborn screening and family studies in Austria. Eur J Pediatr 2001;160:277-282; | F15: TRUE | G15: FALSE | H15: Riesgo: Retraso mental | I15: {=IF(H15="","",VLOOKUP(H15,_xludf.HSTACK(#REF!,#REF!),2,FALSE))} -> #NAME? | J15: No encuentro ese valor en la fuente
A16: UC1-F1-P1-S1-M1 | B16: #BTD_Manif_DevelopmentalDelay_U | C16: UtilityParameter | E16: #hasDescription: Desutilidad anual asociada a retraso del desarrollo; #appliesOneTime: false; #hasExpectedValue: 0.29; | F16: FALSE | G16: TRUE | H16: Utilidad: Retraso mental | I16: {=IF(H16="","",VLOOKUP(H16,_xludf.HSTACK(#REF!,#REF!),2,FALSE))} -> #NAME? | J16: Posible alucinación. Sin fuente
A17: UC1-F1-P1-S1-M1 | B17: #BTD_Manif_HearingLoss | C17: Manifestation | E17: #hasDescription: Pérdida auditiva neurosensorial; | F17: FALSE | G17: FALSE | H17: Manifestación: Problemas de audición | I17: {=IF(H17="","",VLOOKUP(H17,_xludf.HSTACK(#REF!,#REF!),2,FALSE))} -> #NAME?
A18: UC1-F1-P1-S1-M1 | B18: #BTD_Manif_HearingLoss_Prob_LateTraeatment | C18: Parameter | E18: #hasDescription: Probabilidad de pérdida auditiva persistente con tratamiento tardío; #hasExpectedValue: 0.36; #hasSource: Weber P et al. Outcome in patients with profound biotinidase deficiency: relevance of newborn screening. Dev Med Child Neurol 2004;46:481-4; | F18: TRUE | G18: FALSE | H18: Riesgo: Problemas de audición | I18: {=IF(H18="","",VLOOKUP(H18,_xludf.HSTACK(#REF!,#REF!),2,FALSE))} -> #NAME? | J18: No encuentro ese valor en la fuente
